{
 "cells": [
  {
   "cell_type": "code",
   "execution_count": 33,
   "metadata": {},
   "outputs": [],
   "source": [
    "import mysql.connector as mariadb"
   ]
  },
  {
   "cell_type": "markdown",
   "metadata": {},
   "source": [
    "ip\n",
    "hostname\n",
    "port\n",
    "current_database\n",
    "\n",
    "localhost\n",
    "raspberrypi\n",
    "3306\n",
    "op_SAI"
   ]
  },
  {
   "cell_type": "code",
   "execution_count": 3,
   "metadata": {},
   "outputs": [
    {
     "name": "stderr",
     "output_type": "stream",
     "text": [
      "ERROR:root:Internal Python error in the inspect module.\n",
      "Below is the traceback from this internal error.\n",
      "\n"
     ]
    },
    {
     "name": "stdout",
     "output_type": "stream",
     "text": [
      "Error connecting to MariaDB Platform: Can't connect to MySQL server on '127.0.0.1' (10061)\n",
      "Traceback (most recent call last):\n",
      "  File \"<ipython-input-3-e2a2f7a8b938>\", line 17, in <module>\n",
      "    conn = mariadb.connect(**config)\n",
      "mariadb.OperationalError: Can't connect to MySQL server on '127.0.0.1' (10061)\n",
      "\n",
      "During handling of the above exception, another exception occurred:\n",
      "\n",
      "Traceback (most recent call last):\n",
      "  File \"C:\\Users\\Philipp\\anaconda3\\envs\\sai_db\\lib\\site-packages\\IPython\\core\\interactiveshell.py\", line 3418, in run_code\n",
      "    exec(code_obj, self.user_global_ns, self.user_ns)\n",
      "  File \"<ipython-input-3-e2a2f7a8b938>\", line 20, in <module>\n",
      "    sys.exit(1)\n",
      "SystemExit: 1\n",
      "\n",
      "During handling of the above exception, another exception occurred:\n",
      "\n",
      "Traceback (most recent call last):\n",
      "  File \"C:\\Users\\Philipp\\anaconda3\\envs\\sai_db\\lib\\site-packages\\IPython\\core\\ultratb.py\", line 1170, in get_records\n",
      "    return _fixed_getinnerframes(etb, number_of_lines_of_context, tb_offset)\n",
      "  File \"C:\\Users\\Philipp\\anaconda3\\envs\\sai_db\\lib\\site-packages\\IPython\\core\\ultratb.py\", line 316, in wrapped\n",
      "    return f(*args, **kwargs)\n",
      "  File \"C:\\Users\\Philipp\\anaconda3\\envs\\sai_db\\lib\\site-packages\\IPython\\core\\ultratb.py\", line 350, in _fixed_getinnerframes\n",
      "    records = fix_frame_records_filenames(inspect.getinnerframes(etb, context))\n",
      "  File \"C:\\Users\\Philipp\\anaconda3\\envs\\sai_db\\lib\\inspect.py\", line 1529, in getinnerframes\n",
      "    frameinfo = (tb.tb_frame,) + getframeinfo(tb, context)\n",
      "AttributeError: 'tuple' object has no attribute 'tb_frame'\n"
     ]
    },
    {
     "ename": "TypeError",
     "evalue": "object of type 'NoneType' has no len()",
     "output_type": "error",
     "traceback": [
      "\u001b[1;31m---------------------------------------------------------------------------\u001b[0m",
      "\u001b[1;31mOperationalError\u001b[0m                          Traceback (most recent call last)",
      "\u001b[1;32m<ipython-input-3-e2a2f7a8b938>\u001b[0m in \u001b[0;36m<module>\u001b[1;34m\u001b[0m\n\u001b[0;32m     16\u001b[0m \u001b[1;32mtry\u001b[0m\u001b[1;33m:\u001b[0m\u001b[1;33m\u001b[0m\u001b[1;33m\u001b[0m\u001b[0m\n\u001b[1;32m---> 17\u001b[1;33m     \u001b[0mconn\u001b[0m \u001b[1;33m=\u001b[0m \u001b[0mmariadb\u001b[0m\u001b[1;33m.\u001b[0m\u001b[0mconnect\u001b[0m\u001b[1;33m(\u001b[0m\u001b[1;33m**\u001b[0m\u001b[0mconfig\u001b[0m\u001b[1;33m)\u001b[0m\u001b[1;33m\u001b[0m\u001b[1;33m\u001b[0m\u001b[0m\n\u001b[0m\u001b[0;32m     18\u001b[0m \u001b[1;32mexcept\u001b[0m \u001b[0mmariadb\u001b[0m\u001b[1;33m.\u001b[0m\u001b[0mError\u001b[0m \u001b[1;32mas\u001b[0m \u001b[0me\u001b[0m\u001b[1;33m:\u001b[0m\u001b[1;33m\u001b[0m\u001b[1;33m\u001b[0m\u001b[0m\n",
      "\u001b[1;31mOperationalError\u001b[0m: Can't connect to MySQL server on '127.0.0.1' (10061)",
      "\nDuring handling of the above exception, another exception occurred:\n",
      "\u001b[1;31mSystemExit\u001b[0m                                Traceback (most recent call last)",
      "    \u001b[1;31m[... skipping hidden 1 frame]\u001b[0m\n",
      "\u001b[1;32m<ipython-input-3-e2a2f7a8b938>\u001b[0m in \u001b[0;36m<module>\u001b[1;34m\u001b[0m\n\u001b[0;32m     19\u001b[0m     \u001b[0mprint\u001b[0m\u001b[1;33m(\u001b[0m\u001b[1;34mf\"Error connecting to MariaDB Platform: {e}\"\u001b[0m\u001b[1;33m)\u001b[0m\u001b[1;33m\u001b[0m\u001b[1;33m\u001b[0m\u001b[0m\n\u001b[1;32m---> 20\u001b[1;33m     \u001b[0msys\u001b[0m\u001b[1;33m.\u001b[0m\u001b[0mexit\u001b[0m\u001b[1;33m(\u001b[0m\u001b[1;36m1\u001b[0m\u001b[1;33m)\u001b[0m\u001b[1;33m\u001b[0m\u001b[1;33m\u001b[0m\u001b[0m\n\u001b[0m\u001b[0;32m     21\u001b[0m \u001b[1;33m\u001b[0m\u001b[0m\n",
      "\u001b[1;31mSystemExit\u001b[0m: 1",
      "\nDuring handling of the above exception, another exception occurred:\n",
      "\u001b[1;31mTypeError\u001b[0m                                 Traceback (most recent call last)",
      "    \u001b[1;31m[... skipping hidden 1 frame]\u001b[0m\n",
      "\u001b[1;32m~\\anaconda3\\envs\\sai_db\\lib\\site-packages\\IPython\\core\\interactiveshell.py\u001b[0m in \u001b[0;36mshowtraceback\u001b[1;34m(self, exc_tuple, filename, tb_offset, exception_only, running_compiled_code)\u001b[0m\n\u001b[0;32m   2036\u001b[0m                     stb = ['An exception has occurred, use %tb to see '\n\u001b[0;32m   2037\u001b[0m                            'the full traceback.\\n']\n\u001b[1;32m-> 2038\u001b[1;33m                     stb.extend(self.InteractiveTB.get_exception_only(etype,\n\u001b[0m\u001b[0;32m   2039\u001b[0m                                                                      value))\n\u001b[0;32m   2040\u001b[0m                 \u001b[1;32melse\u001b[0m\u001b[1;33m:\u001b[0m\u001b[1;33m\u001b[0m\u001b[1;33m\u001b[0m\u001b[0m\n",
      "\u001b[1;32m~\\anaconda3\\envs\\sai_db\\lib\\site-packages\\IPython\\core\\ultratb.py\u001b[0m in \u001b[0;36mget_exception_only\u001b[1;34m(self, etype, value)\u001b[0m\n\u001b[0;32m    821\u001b[0m         \u001b[0mvalue\u001b[0m \u001b[1;33m:\u001b[0m \u001b[0mexception\u001b[0m \u001b[0mvalue\u001b[0m\u001b[1;33m\u001b[0m\u001b[1;33m\u001b[0m\u001b[0m\n\u001b[0;32m    822\u001b[0m         \"\"\"\n\u001b[1;32m--> 823\u001b[1;33m         \u001b[1;32mreturn\u001b[0m \u001b[0mListTB\u001b[0m\u001b[1;33m.\u001b[0m\u001b[0mstructured_traceback\u001b[0m\u001b[1;33m(\u001b[0m\u001b[0mself\u001b[0m\u001b[1;33m,\u001b[0m \u001b[0metype\u001b[0m\u001b[1;33m,\u001b[0m \u001b[0mvalue\u001b[0m\u001b[1;33m)\u001b[0m\u001b[1;33m\u001b[0m\u001b[1;33m\u001b[0m\u001b[0m\n\u001b[0m\u001b[0;32m    824\u001b[0m \u001b[1;33m\u001b[0m\u001b[0m\n\u001b[0;32m    825\u001b[0m     \u001b[1;32mdef\u001b[0m \u001b[0mshow_exception_only\u001b[0m\u001b[1;33m(\u001b[0m\u001b[0mself\u001b[0m\u001b[1;33m,\u001b[0m \u001b[0metype\u001b[0m\u001b[1;33m,\u001b[0m \u001b[0mevalue\u001b[0m\u001b[1;33m)\u001b[0m\u001b[1;33m:\u001b[0m\u001b[1;33m\u001b[0m\u001b[1;33m\u001b[0m\u001b[0m\n",
      "\u001b[1;32m~\\anaconda3\\envs\\sai_db\\lib\\site-packages\\IPython\\core\\ultratb.py\u001b[0m in \u001b[0;36mstructured_traceback\u001b[1;34m(self, etype, evalue, etb, tb_offset, context)\u001b[0m\n\u001b[0;32m    696\u001b[0m             \u001b[0mchained_exceptions_tb_offset\u001b[0m \u001b[1;33m=\u001b[0m \u001b[1;36m0\u001b[0m\u001b[1;33m\u001b[0m\u001b[1;33m\u001b[0m\u001b[0m\n\u001b[0;32m    697\u001b[0m             out_list = (\n\u001b[1;32m--> 698\u001b[1;33m                 self.structured_traceback(\n\u001b[0m\u001b[0;32m    699\u001b[0m                     \u001b[0metype\u001b[0m\u001b[1;33m,\u001b[0m \u001b[0mevalue\u001b[0m\u001b[1;33m,\u001b[0m \u001b[1;33m(\u001b[0m\u001b[0metb\u001b[0m\u001b[1;33m,\u001b[0m \u001b[0mchained_exc_ids\u001b[0m\u001b[1;33m)\u001b[0m\u001b[1;33m,\u001b[0m\u001b[1;33m\u001b[0m\u001b[1;33m\u001b[0m\u001b[0m\n\u001b[0;32m    700\u001b[0m                     chained_exceptions_tb_offset, context)\n",
      "\u001b[1;32m~\\anaconda3\\envs\\sai_db\\lib\\site-packages\\IPython\\core\\ultratb.py\u001b[0m in \u001b[0;36mstructured_traceback\u001b[1;34m(self, etype, value, tb, tb_offset, number_of_lines_of_context)\u001b[0m\n\u001b[0;32m   1434\u001b[0m         \u001b[1;32melse\u001b[0m\u001b[1;33m:\u001b[0m\u001b[1;33m\u001b[0m\u001b[1;33m\u001b[0m\u001b[0m\n\u001b[0;32m   1435\u001b[0m             \u001b[0mself\u001b[0m\u001b[1;33m.\u001b[0m\u001b[0mtb\u001b[0m \u001b[1;33m=\u001b[0m \u001b[0mtb\u001b[0m\u001b[1;33m\u001b[0m\u001b[1;33m\u001b[0m\u001b[0m\n\u001b[1;32m-> 1436\u001b[1;33m         return FormattedTB.structured_traceback(\n\u001b[0m\u001b[0;32m   1437\u001b[0m             self, etype, value, tb, tb_offset, number_of_lines_of_context)\n\u001b[0;32m   1438\u001b[0m \u001b[1;33m\u001b[0m\u001b[0m\n",
      "\u001b[1;32m~\\anaconda3\\envs\\sai_db\\lib\\site-packages\\IPython\\core\\ultratb.py\u001b[0m in \u001b[0;36mstructured_traceback\u001b[1;34m(self, etype, value, tb, tb_offset, number_of_lines_of_context)\u001b[0m\n\u001b[0;32m   1334\u001b[0m         \u001b[1;32mif\u001b[0m \u001b[0mmode\u001b[0m \u001b[1;32min\u001b[0m \u001b[0mself\u001b[0m\u001b[1;33m.\u001b[0m\u001b[0mverbose_modes\u001b[0m\u001b[1;33m:\u001b[0m\u001b[1;33m\u001b[0m\u001b[1;33m\u001b[0m\u001b[0m\n\u001b[0;32m   1335\u001b[0m             \u001b[1;31m# Verbose modes need a full traceback\u001b[0m\u001b[1;33m\u001b[0m\u001b[1;33m\u001b[0m\u001b[1;33m\u001b[0m\u001b[0m\n\u001b[1;32m-> 1336\u001b[1;33m             return VerboseTB.structured_traceback(\n\u001b[0m\u001b[0;32m   1337\u001b[0m                 \u001b[0mself\u001b[0m\u001b[1;33m,\u001b[0m \u001b[0metype\u001b[0m\u001b[1;33m,\u001b[0m \u001b[0mvalue\u001b[0m\u001b[1;33m,\u001b[0m \u001b[0mtb\u001b[0m\u001b[1;33m,\u001b[0m \u001b[0mtb_offset\u001b[0m\u001b[1;33m,\u001b[0m \u001b[0mnumber_of_lines_of_context\u001b[0m\u001b[1;33m\u001b[0m\u001b[1;33m\u001b[0m\u001b[0m\n\u001b[0;32m   1338\u001b[0m             )\n",
      "\u001b[1;32m~\\anaconda3\\envs\\sai_db\\lib\\site-packages\\IPython\\core\\ultratb.py\u001b[0m in \u001b[0;36mstructured_traceback\u001b[1;34m(self, etype, evalue, etb, tb_offset, number_of_lines_of_context)\u001b[0m\n\u001b[0;32m   1191\u001b[0m         \u001b[1;34m\"\"\"Return a nice text document describing the traceback.\"\"\"\u001b[0m\u001b[1;33m\u001b[0m\u001b[1;33m\u001b[0m\u001b[0m\n\u001b[0;32m   1192\u001b[0m \u001b[1;33m\u001b[0m\u001b[0m\n\u001b[1;32m-> 1193\u001b[1;33m         formatted_exception = self.format_exception_as_a_whole(etype, evalue, etb, number_of_lines_of_context,\n\u001b[0m\u001b[0;32m   1194\u001b[0m                                                                tb_offset)\n\u001b[0;32m   1195\u001b[0m \u001b[1;33m\u001b[0m\u001b[0m\n",
      "\u001b[1;32m~\\anaconda3\\envs\\sai_db\\lib\\site-packages\\IPython\\core\\ultratb.py\u001b[0m in \u001b[0;36mformat_exception_as_a_whole\u001b[1;34m(self, etype, evalue, etb, number_of_lines_of_context, tb_offset)\u001b[0m\n\u001b[0;32m   1149\u001b[0m \u001b[1;33m\u001b[0m\u001b[0m\n\u001b[0;32m   1150\u001b[0m \u001b[1;33m\u001b[0m\u001b[0m\n\u001b[1;32m-> 1151\u001b[1;33m         \u001b[0mlast_unique\u001b[0m\u001b[1;33m,\u001b[0m \u001b[0mrecursion_repeat\u001b[0m \u001b[1;33m=\u001b[0m \u001b[0mfind_recursion\u001b[0m\u001b[1;33m(\u001b[0m\u001b[0morig_etype\u001b[0m\u001b[1;33m,\u001b[0m \u001b[0mevalue\u001b[0m\u001b[1;33m,\u001b[0m \u001b[0mrecords\u001b[0m\u001b[1;33m)\u001b[0m\u001b[1;33m\u001b[0m\u001b[1;33m\u001b[0m\u001b[0m\n\u001b[0m\u001b[0;32m   1152\u001b[0m \u001b[1;33m\u001b[0m\u001b[0m\n\u001b[0;32m   1153\u001b[0m         \u001b[0mframes\u001b[0m \u001b[1;33m=\u001b[0m \u001b[0mself\u001b[0m\u001b[1;33m.\u001b[0m\u001b[0mformat_records\u001b[0m\u001b[1;33m(\u001b[0m\u001b[0mrecords\u001b[0m\u001b[1;33m,\u001b[0m \u001b[0mlast_unique\u001b[0m\u001b[1;33m,\u001b[0m \u001b[0mrecursion_repeat\u001b[0m\u001b[1;33m)\u001b[0m\u001b[1;33m\u001b[0m\u001b[1;33m\u001b[0m\u001b[0m\n",
      "\u001b[1;32m~\\anaconda3\\envs\\sai_db\\lib\\site-packages\\IPython\\core\\ultratb.py\u001b[0m in \u001b[0;36mfind_recursion\u001b[1;34m(etype, value, records)\u001b[0m\n\u001b[0;32m    449\u001b[0m     \u001b[1;31m# first frame (from in to out) that looks different.\u001b[0m\u001b[1;33m\u001b[0m\u001b[1;33m\u001b[0m\u001b[1;33m\u001b[0m\u001b[0m\n\u001b[0;32m    450\u001b[0m     \u001b[1;32mif\u001b[0m \u001b[1;32mnot\u001b[0m \u001b[0mis_recursion_error\u001b[0m\u001b[1;33m(\u001b[0m\u001b[0metype\u001b[0m\u001b[1;33m,\u001b[0m \u001b[0mvalue\u001b[0m\u001b[1;33m,\u001b[0m \u001b[0mrecords\u001b[0m\u001b[1;33m)\u001b[0m\u001b[1;33m:\u001b[0m\u001b[1;33m\u001b[0m\u001b[1;33m\u001b[0m\u001b[0m\n\u001b[1;32m--> 451\u001b[1;33m         \u001b[1;32mreturn\u001b[0m \u001b[0mlen\u001b[0m\u001b[1;33m(\u001b[0m\u001b[0mrecords\u001b[0m\u001b[1;33m)\u001b[0m\u001b[1;33m,\u001b[0m \u001b[1;36m0\u001b[0m\u001b[1;33m\u001b[0m\u001b[1;33m\u001b[0m\u001b[0m\n\u001b[0m\u001b[0;32m    452\u001b[0m \u001b[1;33m\u001b[0m\u001b[0m\n\u001b[0;32m    453\u001b[0m     \u001b[1;31m# Select filename, lineno, func_name to track frames with\u001b[0m\u001b[1;33m\u001b[0m\u001b[1;33m\u001b[0m\u001b[1;33m\u001b[0m\u001b[0m\n",
      "\u001b[1;31mTypeError\u001b[0m: object of type 'NoneType' has no len()"
     ]
    }
   ],
   "source": [
    "# Module Imports\n",
    "import mariadb\n",
    "import sys\n",
    "\n",
    "############### CONFIGURE THIS ###################\n",
    "config = {\n",
    "    'user': 'ps01', # dummy\n",
    "    'password': 'zmVr8xg0v42qtqsE', # dummy\n",
    "    'host': '127.0.0.1', # should this be different?\n",
    "    'port': 3306,\n",
    "    'database': 'op_SAI'\n",
    "}\n",
    "##################################################\n",
    "\n",
    "# Connect to MariaDB Platform\n",
    "try:\n",
    "    conn = mariadb.connect(**config)\n",
    "except mariadb.Error as e:\n",
    "    print(f\"Error connecting to MariaDB Platform: {e}\")\n",
    "    sys.exit(1)\n",
    "\n",
    "# Get Cursor\n",
    "cur = conn.cursor()"
   ]
  },
  {
   "cell_type": "code",
   "execution_count": 24,
   "metadata": {},
   "outputs": [],
   "source": [
    "def print_func(**kwargs):\n",
    "    print(kwargs)"
   ]
  },
  {
   "cell_type": "code",
   "execution_count": 25,
   "metadata": {},
   "outputs": [
    {
     "name": "stdout",
     "output_type": "stream",
     "text": [
      "{'user': 'ps01', 'password': 'zmVr8xg0v42qtqsE', 'host': '127.0.0.1', 'port': 3306, 'database': 'op_SAI', 'charset': 'utf8mb4'}\n"
     ]
    }
   ],
   "source": [
    "print_func(**config)"
   ]
  },
  {
   "cell_type": "code",
   "execution_count": 29,
   "metadata": {},
   "outputs": [
    {
     "ename": "OperationalError",
     "evalue": "(2003, \"Can't connect to MySQL server on '127.0.0.1' ([WinError 10061] No connection could be made because the target machine actively refused it)\")",
     "output_type": "error",
     "traceback": [
      "\u001b[1;31m---------------------------------------------------------------------------\u001b[0m",
      "\u001b[1;31mConnectionRefusedError\u001b[0m                    Traceback (most recent call last)",
      "\u001b[1;32m~\\anaconda3\\envs\\sai_db\\lib\\site-packages\\pymysql\\connections.py\u001b[0m in \u001b[0;36mconnect\u001b[1;34m(self, sock)\u001b[0m\n\u001b[0;32m    568\u001b[0m                         \u001b[1;32mtry\u001b[0m\u001b[1;33m:\u001b[0m\u001b[1;33m\u001b[0m\u001b[1;33m\u001b[0m\u001b[0m\n\u001b[1;32m--> 569\u001b[1;33m                             sock = socket.create_connection(\n\u001b[0m\u001b[0;32m    570\u001b[0m                                 \u001b[1;33m(\u001b[0m\u001b[0mself\u001b[0m\u001b[1;33m.\u001b[0m\u001b[0mhost\u001b[0m\u001b[1;33m,\u001b[0m \u001b[0mself\u001b[0m\u001b[1;33m.\u001b[0m\u001b[0mport\u001b[0m\u001b[1;33m)\u001b[0m\u001b[1;33m,\u001b[0m \u001b[0mself\u001b[0m\u001b[1;33m.\u001b[0m\u001b[0mconnect_timeout\u001b[0m\u001b[1;33m,\u001b[0m\u001b[1;33m\u001b[0m\u001b[1;33m\u001b[0m\u001b[0m\n",
      "\u001b[1;32m~\\anaconda3\\envs\\sai_db\\lib\\socket.py\u001b[0m in \u001b[0;36mcreate_connection\u001b[1;34m(address, timeout, source_address)\u001b[0m\n\u001b[0;32m    842\u001b[0m         \u001b[1;32mtry\u001b[0m\u001b[1;33m:\u001b[0m\u001b[1;33m\u001b[0m\u001b[1;33m\u001b[0m\u001b[0m\n\u001b[1;32m--> 843\u001b[1;33m             \u001b[1;32mraise\u001b[0m \u001b[0merr\u001b[0m\u001b[1;33m\u001b[0m\u001b[1;33m\u001b[0m\u001b[0m\n\u001b[0m\u001b[0;32m    844\u001b[0m         \u001b[1;32mfinally\u001b[0m\u001b[1;33m:\u001b[0m\u001b[1;33m\u001b[0m\u001b[1;33m\u001b[0m\u001b[0m\n",
      "\u001b[1;32m~\\anaconda3\\envs\\sai_db\\lib\\socket.py\u001b[0m in \u001b[0;36mcreate_connection\u001b[1;34m(address, timeout, source_address)\u001b[0m\n\u001b[0;32m    830\u001b[0m                 \u001b[0msock\u001b[0m\u001b[1;33m.\u001b[0m\u001b[0mbind\u001b[0m\u001b[1;33m(\u001b[0m\u001b[0msource_address\u001b[0m\u001b[1;33m)\u001b[0m\u001b[1;33m\u001b[0m\u001b[1;33m\u001b[0m\u001b[0m\n\u001b[1;32m--> 831\u001b[1;33m             \u001b[0msock\u001b[0m\u001b[1;33m.\u001b[0m\u001b[0mconnect\u001b[0m\u001b[1;33m(\u001b[0m\u001b[0msa\u001b[0m\u001b[1;33m)\u001b[0m\u001b[1;33m\u001b[0m\u001b[1;33m\u001b[0m\u001b[0m\n\u001b[0m\u001b[0;32m    832\u001b[0m             \u001b[1;31m# Break explicitly a reference cycle\u001b[0m\u001b[1;33m\u001b[0m\u001b[1;33m\u001b[0m\u001b[1;33m\u001b[0m\u001b[0m\n",
      "\u001b[1;31mConnectionRefusedError\u001b[0m: [WinError 10061] No connection could be made because the target machine actively refused it",
      "\nDuring handling of the above exception, another exception occurred:\n",
      "\u001b[1;31mOperationalError\u001b[0m                          Traceback (most recent call last)",
      "\u001b[1;32m<ipython-input-29-7050c5ab36dd>\u001b[0m in \u001b[0;36m<module>\u001b[1;34m\u001b[0m\n\u001b[0;32m     13\u001b[0m \u001b[1;33m\u001b[0m\u001b[0m\n\u001b[0;32m     14\u001b[0m \u001b[1;31m# Open database connection\u001b[0m\u001b[1;33m\u001b[0m\u001b[1;33m\u001b[0m\u001b[1;33m\u001b[0m\u001b[0m\n\u001b[1;32m---> 15\u001b[1;33m \u001b[0mdb\u001b[0m \u001b[1;33m=\u001b[0m \u001b[0mpymysql\u001b[0m\u001b[1;33m.\u001b[0m\u001b[0mconnect\u001b[0m\u001b[1;33m(\u001b[0m\u001b[1;33m**\u001b[0m\u001b[0mconfig\u001b[0m\u001b[1;33m)\u001b[0m\u001b[1;33m\u001b[0m\u001b[1;33m\u001b[0m\u001b[0m\n\u001b[0m\u001b[0;32m     16\u001b[0m \u001b[1;33m\u001b[0m\u001b[0m\n\u001b[0;32m     17\u001b[0m \u001b[1;31m# prepare a cursor object using cursor() method\u001b[0m\u001b[1;33m\u001b[0m\u001b[1;33m\u001b[0m\u001b[1;33m\u001b[0m\u001b[0m\n",
      "\u001b[1;32m~\\anaconda3\\envs\\sai_db\\lib\\site-packages\\pymysql\\__init__.py\u001b[0m in \u001b[0;36mConnect\u001b[1;34m(*args, **kwargs)\u001b[0m\n\u001b[0;32m     92\u001b[0m     \"\"\"\n\u001b[0;32m     93\u001b[0m     \u001b[1;32mfrom\u001b[0m \u001b[1;33m.\u001b[0m\u001b[0mconnections\u001b[0m \u001b[1;32mimport\u001b[0m \u001b[0mConnection\u001b[0m\u001b[1;33m\u001b[0m\u001b[1;33m\u001b[0m\u001b[0m\n\u001b[1;32m---> 94\u001b[1;33m     \u001b[1;32mreturn\u001b[0m \u001b[0mConnection\u001b[0m\u001b[1;33m(\u001b[0m\u001b[1;33m*\u001b[0m\u001b[0margs\u001b[0m\u001b[1;33m,\u001b[0m \u001b[1;33m**\u001b[0m\u001b[0mkwargs\u001b[0m\u001b[1;33m)\u001b[0m\u001b[1;33m\u001b[0m\u001b[1;33m\u001b[0m\u001b[0m\n\u001b[0m\u001b[0;32m     95\u001b[0m \u001b[1;33m\u001b[0m\u001b[0m\n\u001b[0;32m     96\u001b[0m \u001b[1;32mfrom\u001b[0m \u001b[1;33m.\u001b[0m \u001b[1;32mimport\u001b[0m \u001b[0mconnections\u001b[0m \u001b[1;32mas\u001b[0m \u001b[0m_orig_conn\u001b[0m\u001b[1;33m\u001b[0m\u001b[1;33m\u001b[0m\u001b[0m\n",
      "\u001b[1;32m~\\anaconda3\\envs\\sai_db\\lib\\site-packages\\pymysql\\connections.py\u001b[0m in \u001b[0;36m__init__\u001b[1;34m(self, host, user, password, database, port, unix_socket, charset, sql_mode, read_default_file, conv, use_unicode, client_flag, cursorclass, init_command, connect_timeout, ssl, read_default_group, compress, named_pipe, autocommit, db, passwd, local_infile, max_allowed_packet, defer_connect, auth_plugin_map, read_timeout, write_timeout, bind_address, binary_prefix, program_name, server_public_key)\u001b[0m\n\u001b[0;32m    325\u001b[0m             \u001b[0mself\u001b[0m\u001b[1;33m.\u001b[0m\u001b[0m_sock\u001b[0m \u001b[1;33m=\u001b[0m \u001b[1;32mNone\u001b[0m\u001b[1;33m\u001b[0m\u001b[1;33m\u001b[0m\u001b[0m\n\u001b[0;32m    326\u001b[0m         \u001b[1;32melse\u001b[0m\u001b[1;33m:\u001b[0m\u001b[1;33m\u001b[0m\u001b[1;33m\u001b[0m\u001b[0m\n\u001b[1;32m--> 327\u001b[1;33m             \u001b[0mself\u001b[0m\u001b[1;33m.\u001b[0m\u001b[0mconnect\u001b[0m\u001b[1;33m(\u001b[0m\u001b[1;33m)\u001b[0m\u001b[1;33m\u001b[0m\u001b[1;33m\u001b[0m\u001b[0m\n\u001b[0m\u001b[0;32m    328\u001b[0m \u001b[1;33m\u001b[0m\u001b[0m\n\u001b[0;32m    329\u001b[0m     \u001b[1;32mdef\u001b[0m \u001b[0m_create_ssl_ctx\u001b[0m\u001b[1;33m(\u001b[0m\u001b[0mself\u001b[0m\u001b[1;33m,\u001b[0m \u001b[0msslp\u001b[0m\u001b[1;33m)\u001b[0m\u001b[1;33m:\u001b[0m\u001b[1;33m\u001b[0m\u001b[1;33m\u001b[0m\u001b[0m\n",
      "\u001b[1;32m~\\anaconda3\\envs\\sai_db\\lib\\site-packages\\pymysql\\connections.py\u001b[0m in \u001b[0;36mconnect\u001b[1;34m(self, sock)\u001b[0m\n\u001b[0;32m    617\u001b[0m                 \u001b[0mexc\u001b[0m\u001b[1;33m.\u001b[0m\u001b[0mtraceback\u001b[0m \u001b[1;33m=\u001b[0m \u001b[0mtraceback\u001b[0m\u001b[1;33m.\u001b[0m\u001b[0mformat_exc\u001b[0m\u001b[1;33m(\u001b[0m\u001b[1;33m)\u001b[0m\u001b[1;33m\u001b[0m\u001b[1;33m\u001b[0m\u001b[0m\n\u001b[0;32m    618\u001b[0m                 \u001b[1;32mif\u001b[0m \u001b[0mDEBUG\u001b[0m\u001b[1;33m:\u001b[0m \u001b[0mprint\u001b[0m\u001b[1;33m(\u001b[0m\u001b[0mexc\u001b[0m\u001b[1;33m.\u001b[0m\u001b[0mtraceback\u001b[0m\u001b[1;33m)\u001b[0m\u001b[1;33m\u001b[0m\u001b[1;33m\u001b[0m\u001b[0m\n\u001b[1;32m--> 619\u001b[1;33m                 \u001b[1;32mraise\u001b[0m \u001b[0mexc\u001b[0m\u001b[1;33m\u001b[0m\u001b[1;33m\u001b[0m\u001b[0m\n\u001b[0m\u001b[0;32m    620\u001b[0m \u001b[1;33m\u001b[0m\u001b[0m\n\u001b[0;32m    621\u001b[0m             \u001b[1;31m# If e is neither DatabaseError or IOError, It's a bug.\u001b[0m\u001b[1;33m\u001b[0m\u001b[1;33m\u001b[0m\u001b[1;33m\u001b[0m\u001b[0m\n",
      "\u001b[1;31mOperationalError\u001b[0m: (2003, \"Can't connect to MySQL server on '127.0.0.1' ([WinError 10061] No connection could be made because the target machine actively refused it)\")"
     ]
    }
   ],
   "source": [
    "import pymysql\n",
    "\n",
    "############### CONFIGURE THIS ###################\n",
    "config = {\n",
    "    'user': 'ps01', # dummy\n",
    "    'password': 'zmVr8xg0v42qtqsE', # dummy\n",
    "    'host': '127.0.0.1', # should this be different?\n",
    "    'port': 3306,\n",
    "    'db': 'op_SAI',\n",
    "    'charset':'utf8mb4'\n",
    "}\n",
    "##################################################\n",
    "\n",
    "# Open database connection\n",
    "db = pymysql.connect(**config)\n",
    "\n",
    "# prepare a cursor object using cursor() method\n",
    "cursor = db.cursor()\n",
    "\n",
    "# execute SQL query using execute() method.\n",
    "cursor.execute(\"SELECT VERSION()\")\n",
    "\n",
    "# Fetch a single row using fetchone() method.\n",
    "data = cursor.fetchone()\n",
    "print (\"Database version : {0}\".format(data))\n",
    "\n",
    "# disconnect from server\n",
    "db.close()"
   ]
  },
  {
   "cell_type": "code",
   "execution_count": 40,
   "metadata": {},
   "outputs": [
    {
     "ename": "InterfaceError",
     "evalue": "2003: Can't connect to MySQL server on '127.0.0.1:3306' (10061 No connection could be made because the target machine actively refused it)",
     "output_type": "error",
     "traceback": [
      "\u001b[1;31m---------------------------------------------------------------------------\u001b[0m",
      "\u001b[1;31mConnectionRefusedError\u001b[0m                    Traceback (most recent call last)",
      "\u001b[1;32m~\\anaconda3\\envs\\sai_db\\lib\\site-packages\\mysql\\connector\\network.py\u001b[0m in \u001b[0;36mopen_connection\u001b[1;34m(self)\u001b[0m\n\u001b[0;32m    606\u001b[0m             \u001b[0mself\u001b[0m\u001b[1;33m.\u001b[0m\u001b[0msock\u001b[0m\u001b[1;33m.\u001b[0m\u001b[0msettimeout\u001b[0m\u001b[1;33m(\u001b[0m\u001b[0mself\u001b[0m\u001b[1;33m.\u001b[0m\u001b[0m_connection_timeout\u001b[0m\u001b[1;33m)\u001b[0m\u001b[1;33m\u001b[0m\u001b[1;33m\u001b[0m\u001b[0m\n\u001b[1;32m--> 607\u001b[1;33m             \u001b[0mself\u001b[0m\u001b[1;33m.\u001b[0m\u001b[0msock\u001b[0m\u001b[1;33m.\u001b[0m\u001b[0mconnect\u001b[0m\u001b[1;33m(\u001b[0m\u001b[0msockaddr\u001b[0m\u001b[1;33m)\u001b[0m\u001b[1;33m\u001b[0m\u001b[1;33m\u001b[0m\u001b[0m\n\u001b[0m\u001b[0;32m    608\u001b[0m         \u001b[1;32mexcept\u001b[0m \u001b[0mIOError\u001b[0m \u001b[1;32mas\u001b[0m \u001b[0merr\u001b[0m\u001b[1;33m:\u001b[0m\u001b[1;33m\u001b[0m\u001b[1;33m\u001b[0m\u001b[0m\n",
      "\u001b[1;31mConnectionRefusedError\u001b[0m: [WinError 10061] No connection could be made because the target machine actively refused it",
      "\nDuring handling of the above exception, another exception occurred:\n",
      "\u001b[1;31mInterfaceError\u001b[0m                            Traceback (most recent call last)",
      "\u001b[1;32m<ipython-input-40-4d26c986d890>\u001b[0m in \u001b[0;36m<module>\u001b[1;34m\u001b[0m\n\u001b[0;32m      8\u001b[0m }\n\u001b[0;32m      9\u001b[0m \u001b[1;33m\u001b[0m\u001b[0m\n\u001b[1;32m---> 10\u001b[1;33m \u001b[0mcnx\u001b[0m \u001b[1;33m=\u001b[0m \u001b[0mmariadb\u001b[0m\u001b[1;33m.\u001b[0m\u001b[0mconnect\u001b[0m\u001b[1;33m(\u001b[0m\u001b[1;33m**\u001b[0m\u001b[0mconfig\u001b[0m\u001b[1;33m)\u001b[0m\u001b[1;33m\u001b[0m\u001b[1;33m\u001b[0m\u001b[0m\n\u001b[0m",
      "\u001b[1;32m~\\anaconda3\\envs\\sai_db\\lib\\site-packages\\mysql\\connector\\__init__.py\u001b[0m in \u001b[0;36mconnect\u001b[1;34m(*args, **kwargs)\u001b[0m\n\u001b[0;32m    269\u001b[0m     \u001b[1;32mif\u001b[0m \u001b[0mHAVE_CEXT\u001b[0m \u001b[1;32mand\u001b[0m \u001b[1;32mnot\u001b[0m \u001b[0muse_pure\u001b[0m\u001b[1;33m:\u001b[0m\u001b[1;33m\u001b[0m\u001b[1;33m\u001b[0m\u001b[0m\n\u001b[0;32m    270\u001b[0m         \u001b[1;32mreturn\u001b[0m \u001b[0mCMySQLConnection\u001b[0m\u001b[1;33m(\u001b[0m\u001b[1;33m*\u001b[0m\u001b[0margs\u001b[0m\u001b[1;33m,\u001b[0m \u001b[1;33m**\u001b[0m\u001b[0mkwargs\u001b[0m\u001b[1;33m)\u001b[0m\u001b[1;33m\u001b[0m\u001b[1;33m\u001b[0m\u001b[0m\n\u001b[1;32m--> 271\u001b[1;33m     \u001b[1;32mreturn\u001b[0m \u001b[0mMySQLConnection\u001b[0m\u001b[1;33m(\u001b[0m\u001b[1;33m*\u001b[0m\u001b[0margs\u001b[0m\u001b[1;33m,\u001b[0m \u001b[1;33m**\u001b[0m\u001b[0mkwargs\u001b[0m\u001b[1;33m)\u001b[0m\u001b[1;33m\u001b[0m\u001b[1;33m\u001b[0m\u001b[0m\n\u001b[0m\u001b[0;32m    272\u001b[0m \u001b[0mConnect\u001b[0m \u001b[1;33m=\u001b[0m \u001b[0mconnect\u001b[0m  \u001b[1;31m# pylint: disable=C0103\u001b[0m\u001b[1;33m\u001b[0m\u001b[1;33m\u001b[0m\u001b[0m\n\u001b[0;32m    273\u001b[0m \u001b[1;33m\u001b[0m\u001b[0m\n",
      "\u001b[1;32m~\\anaconda3\\envs\\sai_db\\lib\\site-packages\\mysql\\connector\\connection.py\u001b[0m in \u001b[0;36m__init__\u001b[1;34m(self, *args, **kwargs)\u001b[0m\n\u001b[0;32m    105\u001b[0m         \u001b[1;32mif\u001b[0m \u001b[0mkwargs\u001b[0m\u001b[1;33m:\u001b[0m\u001b[1;33m\u001b[0m\u001b[1;33m\u001b[0m\u001b[0m\n\u001b[0;32m    106\u001b[0m             \u001b[1;32mtry\u001b[0m\u001b[1;33m:\u001b[0m\u001b[1;33m\u001b[0m\u001b[1;33m\u001b[0m\u001b[0m\n\u001b[1;32m--> 107\u001b[1;33m                 \u001b[0mself\u001b[0m\u001b[1;33m.\u001b[0m\u001b[0mconnect\u001b[0m\u001b[1;33m(\u001b[0m\u001b[1;33m**\u001b[0m\u001b[0mkwargs\u001b[0m\u001b[1;33m)\u001b[0m\u001b[1;33m\u001b[0m\u001b[1;33m\u001b[0m\u001b[0m\n\u001b[0m\u001b[0;32m    108\u001b[0m             \u001b[1;32mexcept\u001b[0m\u001b[1;33m:\u001b[0m\u001b[1;33m\u001b[0m\u001b[1;33m\u001b[0m\u001b[0m\n\u001b[0;32m    109\u001b[0m                 \u001b[1;31m# Tidy-up underlying socket on failure\u001b[0m\u001b[1;33m\u001b[0m\u001b[1;33m\u001b[0m\u001b[1;33m\u001b[0m\u001b[0m\n",
      "\u001b[1;32m~\\anaconda3\\envs\\sai_db\\lib\\site-packages\\mysql\\connector\\abstracts.py\u001b[0m in \u001b[0;36mconnect\u001b[1;34m(self, **kwargs)\u001b[0m\n\u001b[0;32m    983\u001b[0m \u001b[1;33m\u001b[0m\u001b[0m\n\u001b[0;32m    984\u001b[0m         \u001b[0mself\u001b[0m\u001b[1;33m.\u001b[0m\u001b[0mdisconnect\u001b[0m\u001b[1;33m(\u001b[0m\u001b[1;33m)\u001b[0m\u001b[1;33m\u001b[0m\u001b[1;33m\u001b[0m\u001b[0m\n\u001b[1;32m--> 985\u001b[1;33m         \u001b[0mself\u001b[0m\u001b[1;33m.\u001b[0m\u001b[0m_open_connection\u001b[0m\u001b[1;33m(\u001b[0m\u001b[1;33m)\u001b[0m\u001b[1;33m\u001b[0m\u001b[1;33m\u001b[0m\u001b[0m\n\u001b[0m\u001b[0;32m    986\u001b[0m         \u001b[1;31m# Server does not allow to run any other statement different from ALTER\u001b[0m\u001b[1;33m\u001b[0m\u001b[1;33m\u001b[0m\u001b[1;33m\u001b[0m\u001b[0m\n\u001b[0;32m    987\u001b[0m         \u001b[1;31m# when user's password has been expired.\u001b[0m\u001b[1;33m\u001b[0m\u001b[1;33m\u001b[0m\u001b[1;33m\u001b[0m\u001b[0m\n",
      "\u001b[1;32m~\\anaconda3\\envs\\sai_db\\lib\\site-packages\\mysql\\connector\\connection.py\u001b[0m in \u001b[0;36m_open_connection\u001b[1;34m(self)\u001b[0m\n\u001b[0;32m    306\u001b[0m         \u001b[0mself\u001b[0m\u001b[1;33m.\u001b[0m\u001b[0m_socket\u001b[0m \u001b[1;33m=\u001b[0m \u001b[0mself\u001b[0m\u001b[1;33m.\u001b[0m\u001b[0m_get_connection\u001b[0m\u001b[1;33m(\u001b[0m\u001b[1;33m)\u001b[0m\u001b[1;33m\u001b[0m\u001b[1;33m\u001b[0m\u001b[0m\n\u001b[0;32m    307\u001b[0m         \u001b[1;32mtry\u001b[0m\u001b[1;33m:\u001b[0m\u001b[1;33m\u001b[0m\u001b[1;33m\u001b[0m\u001b[0m\n\u001b[1;32m--> 308\u001b[1;33m             \u001b[0mself\u001b[0m\u001b[1;33m.\u001b[0m\u001b[0m_socket\u001b[0m\u001b[1;33m.\u001b[0m\u001b[0mopen_connection\u001b[0m\u001b[1;33m(\u001b[0m\u001b[1;33m)\u001b[0m\u001b[1;33m\u001b[0m\u001b[1;33m\u001b[0m\u001b[0m\n\u001b[0m\u001b[0;32m    309\u001b[0m             \u001b[0mself\u001b[0m\u001b[1;33m.\u001b[0m\u001b[0m_do_handshake\u001b[0m\u001b[1;33m(\u001b[0m\u001b[1;33m)\u001b[0m\u001b[1;33m\u001b[0m\u001b[1;33m\u001b[0m\u001b[0m\n\u001b[0;32m    310\u001b[0m             self._do_auth(self._user, self._password,\n",
      "\u001b[1;32m~\\anaconda3\\envs\\sai_db\\lib\\site-packages\\mysql\\connector\\network.py\u001b[0m in \u001b[0;36mopen_connection\u001b[1;34m(self)\u001b[0m\n\u001b[0;32m    607\u001b[0m             \u001b[0mself\u001b[0m\u001b[1;33m.\u001b[0m\u001b[0msock\u001b[0m\u001b[1;33m.\u001b[0m\u001b[0mconnect\u001b[0m\u001b[1;33m(\u001b[0m\u001b[0msockaddr\u001b[0m\u001b[1;33m)\u001b[0m\u001b[1;33m\u001b[0m\u001b[1;33m\u001b[0m\u001b[0m\n\u001b[0;32m    608\u001b[0m         \u001b[1;32mexcept\u001b[0m \u001b[0mIOError\u001b[0m \u001b[1;32mas\u001b[0m \u001b[0merr\u001b[0m\u001b[1;33m:\u001b[0m\u001b[1;33m\u001b[0m\u001b[1;33m\u001b[0m\u001b[0m\n\u001b[1;32m--> 609\u001b[1;33m             raise errors.InterfaceError(\n\u001b[0m\u001b[0;32m    610\u001b[0m                 errno=2003, values=(self.get_address(), _strioerror(err)))\n\u001b[0;32m    611\u001b[0m         \u001b[1;32mexcept\u001b[0m \u001b[0mException\u001b[0m \u001b[1;32mas\u001b[0m \u001b[0merr\u001b[0m\u001b[1;33m:\u001b[0m\u001b[1;33m\u001b[0m\u001b[1;33m\u001b[0m\u001b[0m\n",
      "\u001b[1;31mInterfaceError\u001b[0m: 2003: Can't connect to MySQL server on '127.0.0.1:3306' (10061 No connection could be made because the target machine actively refused it)"
     ]
    }
   ],
   "source": [
    "config = {\n",
    "    'user': 'ps01', # dummy\n",
    "    'password': 'zmVr8xg0v42qtqsE', # dummy\n",
    "    'host': '127.0.0.1',#'https://z0ctawmbn1r701dn.myfritz.net/', # should this be different?\n",
    "    'port': 3306,\n",
    "    'database': 'op_SAI', # name of db?\n",
    "    'raise_on_warnings': True\n",
    "}\n",
    "\n",
    "cnx = mariadb.connect(**config)"
   ]
  },
  {
   "cell_type": "code",
   "execution_count": null,
   "metadata": {},
   "outputs": [],
   "source": [
    "cnx.close()"
   ]
  }
 ],
 "metadata": {
  "kernelspec": {
   "display_name": "Python 3",
   "language": "python",
   "name": "python3"
  },
  "language_info": {
   "codemirror_mode": {
    "name": "ipython",
    "version": 3
   },
   "file_extension": ".py",
   "mimetype": "text/x-python",
   "name": "python",
   "nbconvert_exporter": "python",
   "pygments_lexer": "ipython3",
   "version": "3.9.0"
  }
 },
 "nbformat": 4,
 "nbformat_minor": 4
}
